{
  "additionalMetadata": {
    "cna": "github_m",
    "cveId": "CVE-2024-29033",
    "reason": "Added CPE configurations because not yet analyzed by NVD.",
    "references": [
      "https://github.com/jupyterhub/oauthenticator/commit/5246b09675501b09fb6ed64022099b7644812f60",
      "https://github.com/jupyterhub/oauthenticator/security/advisories/GHSA-55m3-44xf-hg4h",
      "https://trufflesecurity.com/blog/google-oauth-is-broken-sort-of"
    ]
  },
  "adp": {
    "affected": [
      {
        "collectionURL": "https://pypi.org",
        "cpes": [
          "cpe:2.3:a:jupyter:oauthenticator:*:*:*:*:*:*:*:*"
        ],
        "packageName": "oauthenticator",
        "product": "oauthenticator",
        "vendor": "jupyterhub",
        "versions": [
          {
            "lessThan": "16.3.0",
            "status": "affected",
            "version": "0",
            "versionType": "custom"
          }
        ]
      }
    ],
    "providerMetadata": {
      "orgId": "00000000-0000-4000-8000-000000000000",
      "shortName": "anchoreadp"
    }
  }
}